I recently experienced being stuck with the error [In] while executing a Python script, that worked perfectly the other day. 



While connected to my company wifi, the script worked.

But when I ran the same code from my home network, I got the follow error message: 
